<?xml version="1.0"?>
<robot xmlns:xacro="http://www.ros.org/wiki/xacro">

  <!--                                                                      -->
  <!-- MACRO FOR THRUSTER UNITS  -->
  <!--                                                                      -->

  <!-- Provide the propeller mesh in a separate file with the rotation axis
  over propeller's frame X-axis in DAE (Collada) or STL format.
  -->
  <xacro:property name="prop_mesh_file" value="file://$(find triton_description)/meshes/propeller.stl"/>
  <xacro:property name="grabber_claw_mesh_file" value="file://$(find triton_description)/meshes/grabber_claw.STL"/>

  <!--
    Thruster macro with integration of joint and link. The thrusters should
    be initialized in the actuators.xacro file.
  -->
  <xacro:macro name="propeller_macro" params="robot_namespace thruster_id *origin">

    <!--
    Dummy link as place holder for the thruster frame,
    since thrusters can often be inside the collision geometry
    of the vehicle and may cause internal collisions if set otherwise
    -->
    <link name="${robot_namespace}/thruster_${thruster_id}">

      <visual>
        <geometry>
          <mesh filename="${prop_mesh_file}" scale="1 1 1" />
        </geometry>
        <material name="red">
	      	<color rgba="0.8 0.0 0.0 1.0"/>
	      </material>
      </visual>

      <inertial>
        <mass value="0.344" />
        <origin xyz="0 0 0" rpy="0 0 0"/>
        <inertia ixx="0.000000017" ixy="0.0" ixz="0.0"
               iyy="0.000000017" iyz="0.0"
               izz="0.000000017" />
      </inertial>
    </link>

    <!-- Joint between thruster link and vehicle base link -->
    <joint name="${robot_namespace}/thruster_${thruster_id}_joint" type="continuous">
      <xacro:insert_block name="origin" />
      <axis xyz="1 0 0" />
      <parent link="${robot_namespace}/base_link" />
      <child link="${robot_namespace}/thruster_${thruster_id}" />
    </joint>

    <gazebo reference="${robot_namespace}/thruster_${thruster_id}">
     <material>Gazebo/Red</material>
    </gazebo>

    <gazebo>
      <!-- Thruster ROS plugin -->
      <plugin name="${robot_namespace}_${thruster_id}_thruster_model" filename="libuuv_thruster_ros_plugin.so">
        <!-- Name of the thruster link -->
        <linkName>${robot_namespace}/thruster_${thruster_id}</linkName>

        <!-- Name of the joint between thruster and vehicle base link -->
        <jointName>${robot_namespace}/thruster_${thruster_id}_joint</jointName>

        <!-- Make the thruster aware of its id -->
        <thrusterID>${thruster_id}</thrusterID>

        <!-- Gain of the input command signal -->
        <gain>1</gain>

        <!-- Maximum allowed input value for the input signal for thruster unit -->
        <clampMax>0</clampMax>

        <!-- Minimum allowed value for the input signal for thruster unit -->
        <clampMin>0</clampMin>

        <!-- Minimum and maximum thrust force output allowed -->
        <thrustMin>0</thrustMin>
        <thrustMax>0</thrustMax>

        <!--
        Value from 0 to 1 to set the efficiency of the output thrust force
        Default value is 1.0
        -->
        <thrust_efficiency>1</thrust_efficiency>

        <!--
        Value from 0 to 1 to set the efficiency of the propeller as a factor
        to be multiplied to the current value of the state variable at each
        iteration.
        Default value is 1.0
        -->
        <propeller_efficiency>1</propeller_efficiency>

        <!--
        Choose one of the propeller dynamics models below for your implementation
        This will describe the dynamic model for the state variable of your thruster unit,
        which can be, e.g., the angular velocity of the propeller.
        -->

        <!-- 1) Simple zero-order model -->
        <!-- <dynamics>
          <type>ZeroOrder</type>
        </dynamics> -->

        <!-- 2) First order model -->
        <dynamics>
          <type>FirstOrder</type>
          <timeConstant>0.0</timeConstant>
        </dynamics>

        <!-- 3) Yoerger's nonlinear dynamic model
        For information on the model description:
        [1] D. R. Yoerger, J. G. Cooke, and J.-J. E. Slotine, "The influence of
            thruster dynamics on underwater vehicle behavior and their incorporation
            into control system design," IEEE Journal of Oceanic Engineering, vol. 15,
            no. 3, pp. 167-178, Jul. 1990.
        -->
        <!-- <dynamics>
          <type>Yoerger</type>
          <alpha>0.0</alpha>
          <beta>0.0</beta>
        </dynamics> -->

        <!-- 4) Bessa's nonlinear dynamic model
        For information on the model description:
        [2] Bessa, Wallace Moreira, Max Suell Dutra, and Edwin Kreuzer. "Thruster
            dynamics compensation for the positioning of underwater robotic vehicles
            through a fuzzy sliding mode based approach." ABCM Symposium Series in
            Mechatronics. Vol. 2. 2006.
        -->
        <!-- <dynamics>
          <type>Bessa</type>
          <Jmsp>0.0</Jmsp>
          <Kv1>0.0</Kv1>
          <Kv2>0.0</Kv2>
          <Kt>0.0</Kt>
          <Rm>0.0</Rm>
        </dynamics> -->

        <!--
        Choose one of the model for the steady-state curve describing the
        relationship between the state variable and the output thrust force
        -->

        <!-- 1) Basic curve
        Input: x
        Output: thrust
        Function: thrust = rotorConstant * x * abs(x)
        -->
        <conversion>
          <type>Basic</type>
          <rotorConstant>0.0</rotorConstant>
        </conversion>

        <!-- 2) Dead-zone nonlinearity described in Bessa, 2006
        Input: x
        Output: thrust
        Function:
        thrust = rotorConstantL * (x * abs(x) - deltaL), if x * abs(x) <= deltaL
        thrust = 0, if deltaL < x * abs(x) < deltaR
        thrust = rotorConstantR * (x * abs(x) - deltaR), if x * abs(x) >= deltaL
        -->
        <!-- <conversion>
          <type>Bessa</type>
          <rotorConstantL>0.0</rotorConstantL>
          <rotorConstantR>0.0</rotorConstantR>
          <deltaL>0.0</deltaL>
          <deltaR>0.0</deltaR>
        </conversion> -->

        <!-- 3) Linear interpolation
        If you have access to the thruster's data sheet, for example,
        you can enter samples of the curve's input and output values
        and the thruster output will be found through linear interpolation
        of the given samples.
        -->
        <!-- <conversion>
          <type>LinearInterp</type>
          <inputValues>0 1 2 3</inputValues>
          <outputValues>0 1 2 3</outputValues>
        </conversion> -->

      </plugin>
    </gazebo>

    <gazebo reference="${robot_namespace}/thruster_${thruster_id}">
      <selfCollide>false</selfCollide>
    </gazebo>
  </xacro:macro>


<xacro:macro name="grabber_claw_macro" 
params="robot_namespace claw_id *origin">

 <link name="${robot_namespace}/grabber_claw_${claw_id}">

    <inertial>
      <origin xyz="0 0 0" rpy="0 0 0" />
      <mass value="0.0063689" />
      <inertia ixx="2.7098E-06" ixy="1.6284E-06" ixz="1.7604E-22"
        iyy="1.5534E-06" iyz="-1.9905E-22" izz="4.2537E-06" />
    </inertial>

    <visual>
      <origin xyz="0 0 0" rpy="0 0 0" />
      <geometry>
        <mesh
          filename= "${grabber_claw_mesh_file}" scale = "1 1 1" />
      </geometry>
      <material name="claw_color">
        <color rgba="0.89804 0.91765 0.92941 1" />
      </material>
    </visual>

    <collision>
      <origin  xyz="0 0 0" rpy="0 0 0" />
      <geometry>
        <mesh
          filename= "${grabber_claw_mesh_file}" scale = "1 1 1" />
      </geometry>
    </collision>

  </link>

  <joint name="${robot_namespace}/grabber_claw_${claw_id}_joint" type="revolute">
    <xacro:insert_block name="origin"/>
    <parent link="${robot_namespace}/grabber_rod" />
    <child link="${robot_namespace}/grabber_claw_${claw_id}" />
    <axis xyz="0 0 1" />
    <limit
      lower="-0.69"
      upper="0"
      effort="10"
      velocity="5" />
  </joint>
  
</xacro:macro>

</robot>
